[2021-11-18 00:31:16,317] {taskinstance.py:1035} INFO - Dependencies all met for <TaskInstance: mwaa-sm-customer-churn-dag.test-endpoint manual__2021-11-18T08:21:07.224591+00:00 [queued]>
[2021-11-18 00:31:16,381] {taskinstance.py:1035} INFO - Dependencies all met for <TaskInstance: mwaa-sm-customer-churn-dag.test-endpoint manual__2021-11-18T08:21:07.224591+00:00 [queued]>
[2021-11-18 00:31:16,382] {taskinstance.py:1241} INFO - 
--------------------------------------------------------------------------------
[2021-11-18 00:31:16,382] {taskinstance.py:1242} INFO - Starting attempt 1 of 1
[2021-11-18 00:31:16,382] {taskinstance.py:1243} INFO - 
--------------------------------------------------------------------------------
[2021-11-18 00:31:16,403] {taskinstance.py:1262} INFO - Executing <Task(TestOperator): test-endpoint> on 2021-11-18 08:21:07.224591+00:00
[2021-11-18 00:31:16,422] {standard_task_runner.py:76} INFO - Running: ['airflow', 'tasks', 'run', 'mwaa-sm-customer-churn-dag', 'test-endpoint', 'manual__2021-11-18T08:21:07.224591+00:00', '--job-id', '57', '--raw', '--subdir', 'DAGS_FOLDER/mwaa-customer-churn-dag.py', '--cfg-path', '/var/folders/m8/kcmtvg3x5639v8tv9jcxd6700000gn/T/tmpxak_3q6z', '--error-file', '/var/folders/m8/kcmtvg3x5639v8tv9jcxd6700000gn/T/tmp2y_of4h9']
[2021-11-18 00:31:16,425] {standard_task_runner.py:77} INFO - Job 57: Subtask test-endpoint
[2021-11-18 00:31:16,411] {standard_task_runner.py:52} INFO - Started process 17069 to run task
[2021-11-18 00:31:16,502] {logging_mixin.py:109} INFO - Running <TaskInstance: mwaa-sm-customer-churn-dag.test-endpoint manual__2021-11-18T08:21:07.224591+00:00 [running]> on host Shimings-MacBook-Air.local
[2021-11-18 00:31:16,576] {taskinstance.py:1427} INFO - Exporting the following env vars:
AIRFLOW_CTX_DAG_OWNER=airflow
AIRFLOW_CTX_DAG_ID=mwaa-sm-customer-churn-dag
AIRFLOW_CTX_TASK_ID=test-endpoint
AIRFLOW_CTX_EXECUTION_DATE=2021-11-18T08:21:07.224591+00:00
AIRFLOW_CTX_DAG_RUN_ID=manual__2021-11-18T08:21:07.224591+00:00
[2021-11-18 00:31:16,670] {taskinstance.py:1703} ERROR - Task failed with exception
Traceback (most recent call last):
  File "/Users/shimingr/mlops/airflow/venv2/lib/python3.9/site-packages/fsspec/registry.py", line 219, in get_filesystem_class
    register_implementation(protocol, _import_class(bit["class"]))
  File "/Users/shimingr/mlops/airflow/venv2/lib/python3.9/site-packages/fsspec/registry.py", line 242, in _import_class
    mod = importlib.import_module(mod)
  File "/usr/local/Cellar/python@3.9/3.9.7_1/Frameworks/Python.framework/Versions/3.9/lib/python3.9/importlib/__init__.py", line 127, in import_module
    return _bootstrap._gcd_import(name[level:], package, level)
  File "<frozen importlib._bootstrap>", line 1030, in _gcd_import
  File "<frozen importlib._bootstrap>", line 1007, in _find_and_load
  File "<frozen importlib._bootstrap>", line 986, in _find_and_load_unlocked
  File "<frozen importlib._bootstrap>", line 680, in _load_unlocked
  File "<frozen importlib._bootstrap_external>", line 850, in exec_module
  File "<frozen importlib._bootstrap>", line 228, in _call_with_frames_removed
  File "/Users/shimingr/mlops/airflow/venv2/lib/python3.9/site-packages/s3fs/__init__.py", line 1, in <module>
    from .core import S3FileSystem, S3File
  File "/Users/shimingr/mlops/airflow/venv2/lib/python3.9/site-packages/s3fs/core.py", line 12, in <module>
    from fsspec.asyn import AsyncFileSystem, sync, sync_wrapper, maybe_sync
ImportError: cannot import name 'maybe_sync' from 'fsspec.asyn' (/Users/shimingr/mlops/airflow/venv2/lib/python3.9/site-packages/fsspec/asyn.py)

The above exception was the direct cause of the following exception:

Traceback (most recent call last):
  File "/Users/shimingr/mlops/airflow/venv2/lib/python3.9/site-packages/airflow/models/taskinstance.py", line 1332, in _run_raw_task
    self._execute_task_with_callbacks(context)
  File "/Users/shimingr/mlops/airflow/venv2/lib/python3.9/site-packages/airflow/models/taskinstance.py", line 1458, in _execute_task_with_callbacks
    result = self._execute_task(context, self.task)
  File "/Users/shimingr/mlops/airflow/venv2/lib/python3.9/site-packages/airflow/models/taskinstance.py", line 1514, in _execute_task
    result = execute_callable(context=context)
  File "/Users/shimingr/mlops/airflow/dags/custom_operator/test_operator.py", line 23, in execute
    results = pd.read_csv("s3://{}/{}".format(bucket, key), header=None, delimiter=",")
  File "/Users/shimingr/mlops/airflow/venv2/lib/python3.9/site-packages/pandas/util/_decorators.py", line 311, in wrapper
    return func(*args, **kwargs)
  File "/Users/shimingr/mlops/airflow/venv2/lib/python3.9/site-packages/pandas/io/parsers/readers.py", line 586, in read_csv
    return _read(filepath_or_buffer, kwds)
  File "/Users/shimingr/mlops/airflow/venv2/lib/python3.9/site-packages/pandas/io/parsers/readers.py", line 482, in _read
    parser = TextFileReader(filepath_or_buffer, **kwds)
  File "/Users/shimingr/mlops/airflow/venv2/lib/python3.9/site-packages/pandas/io/parsers/readers.py", line 811, in __init__
    self._engine = self._make_engine(self.engine)
  File "/Users/shimingr/mlops/airflow/venv2/lib/python3.9/site-packages/pandas/io/parsers/readers.py", line 1040, in _make_engine
    return mapping[engine](self.f, **self.options)  # type: ignore[call-arg]
  File "/Users/shimingr/mlops/airflow/venv2/lib/python3.9/site-packages/pandas/io/parsers/c_parser_wrapper.py", line 51, in __init__
    self._open_handles(src, kwds)
  File "/Users/shimingr/mlops/airflow/venv2/lib/python3.9/site-packages/pandas/io/parsers/base_parser.py", line 222, in _open_handles
    self.handles = get_handle(
  File "/Users/shimingr/mlops/airflow/venv2/lib/python3.9/site-packages/pandas/io/common.py", line 609, in get_handle
    ioargs = _get_filepath_or_buffer(
  File "/Users/shimingr/mlops/airflow/venv2/lib/python3.9/site-packages/pandas/io/common.py", line 358, in _get_filepath_or_buffer
    file_obj = fsspec.open(
  File "/Users/shimingr/mlops/airflow/venv2/lib/python3.9/site-packages/fsspec/core.py", line 452, in open
    return open_files(
  File "/Users/shimingr/mlops/airflow/venv2/lib/python3.9/site-packages/fsspec/core.py", line 286, in open_files
    fs, fs_token, paths = get_fs_token_paths(
  File "/Users/shimingr/mlops/airflow/venv2/lib/python3.9/site-packages/fsspec/core.py", line 622, in get_fs_token_paths
    cls = get_filesystem_class(protocol)
  File "/Users/shimingr/mlops/airflow/venv2/lib/python3.9/site-packages/fsspec/registry.py", line 221, in get_filesystem_class
    raise ImportError(bit["err"]) from e
ImportError: Install s3fs to access S3
[2021-11-18 00:31:16,754] {taskinstance.py:1270} INFO - Marking task as FAILED. dag_id=mwaa-sm-customer-churn-dag, task_id=test-endpoint, execution_date=20211118T082107, start_date=20211118T083116, end_date=20211118T083116
[2021-11-18 00:31:16,773] {standard_task_runner.py:88} ERROR - Failed to execute job 57 for task test-endpoint
Traceback (most recent call last):
  File "/Users/shimingr/mlops/airflow/venv2/lib/python3.9/site-packages/fsspec/registry.py", line 219, in get_filesystem_class
    register_implementation(protocol, _import_class(bit["class"]))
  File "/Users/shimingr/mlops/airflow/venv2/lib/python3.9/site-packages/fsspec/registry.py", line 242, in _import_class
    mod = importlib.import_module(mod)
  File "/usr/local/Cellar/python@3.9/3.9.7_1/Frameworks/Python.framework/Versions/3.9/lib/python3.9/importlib/__init__.py", line 127, in import_module
    return _bootstrap._gcd_import(name[level:], package, level)
  File "<frozen importlib._bootstrap>", line 1030, in _gcd_import
  File "<frozen importlib._bootstrap>", line 1007, in _find_and_load
  File "<frozen importlib._bootstrap>", line 986, in _find_and_load_unlocked
  File "<frozen importlib._bootstrap>", line 680, in _load_unlocked
  File "<frozen importlib._bootstrap_external>", line 850, in exec_module
  File "<frozen importlib._bootstrap>", line 228, in _call_with_frames_removed
  File "/Users/shimingr/mlops/airflow/venv2/lib/python3.9/site-packages/s3fs/__init__.py", line 1, in <module>
    from .core import S3FileSystem, S3File
  File "/Users/shimingr/mlops/airflow/venv2/lib/python3.9/site-packages/s3fs/core.py", line 12, in <module>
    from fsspec.asyn import AsyncFileSystem, sync, sync_wrapper, maybe_sync
ImportError: cannot import name 'maybe_sync' from 'fsspec.asyn' (/Users/shimingr/mlops/airflow/venv2/lib/python3.9/site-packages/fsspec/asyn.py)

The above exception was the direct cause of the following exception:

Traceback (most recent call last):
  File "/Users/shimingr/mlops/airflow/venv2/lib/python3.9/site-packages/airflow/task/task_runner/standard_task_runner.py", line 85, in _start_by_fork
    args.func(args, dag=self.dag)
  File "/Users/shimingr/mlops/airflow/venv2/lib/python3.9/site-packages/airflow/cli/cli_parser.py", line 48, in command
    return func(*args, **kwargs)
  File "/Users/shimingr/mlops/airflow/venv2/lib/python3.9/site-packages/airflow/utils/cli.py", line 92, in wrapper
    return f(*args, **kwargs)
  File "/Users/shimingr/mlops/airflow/venv2/lib/python3.9/site-packages/airflow/cli/commands/task_command.py", line 292, in task_run
    _run_task_by_selected_method(args, dag, ti)
  File "/Users/shimingr/mlops/airflow/venv2/lib/python3.9/site-packages/airflow/cli/commands/task_command.py", line 107, in _run_task_by_selected_method
    _run_raw_task(args, ti)
  File "/Users/shimingr/mlops/airflow/venv2/lib/python3.9/site-packages/airflow/cli/commands/task_command.py", line 180, in _run_raw_task
    ti._run_raw_task(
  File "/Users/shimingr/mlops/airflow/venv2/lib/python3.9/site-packages/airflow/utils/session.py", line 70, in wrapper
    return func(*args, session=session, **kwargs)
  File "/Users/shimingr/mlops/airflow/venv2/lib/python3.9/site-packages/airflow/models/taskinstance.py", line 1332, in _run_raw_task
    self._execute_task_with_callbacks(context)
  File "/Users/shimingr/mlops/airflow/venv2/lib/python3.9/site-packages/airflow/models/taskinstance.py", line 1458, in _execute_task_with_callbacks
    result = self._execute_task(context, self.task)
  File "/Users/shimingr/mlops/airflow/venv2/lib/python3.9/site-packages/airflow/models/taskinstance.py", line 1514, in _execute_task
    result = execute_callable(context=context)
  File "/Users/shimingr/mlops/airflow/dags/custom_operator/test_operator.py", line 23, in execute
    results = pd.read_csv("s3://{}/{}".format(bucket, key), header=None, delimiter=",")
  File "/Users/shimingr/mlops/airflow/venv2/lib/python3.9/site-packages/pandas/util/_decorators.py", line 311, in wrapper
    return func(*args, **kwargs)
  File "/Users/shimingr/mlops/airflow/venv2/lib/python3.9/site-packages/pandas/io/parsers/readers.py", line 586, in read_csv
    return _read(filepath_or_buffer, kwds)
  File "/Users/shimingr/mlops/airflow/venv2/lib/python3.9/site-packages/pandas/io/parsers/readers.py", line 482, in _read
    parser = TextFileReader(filepath_or_buffer, **kwds)
  File "/Users/shimingr/mlops/airflow/venv2/lib/python3.9/site-packages/pandas/io/parsers/readers.py", line 811, in __init__
    self._engine = self._make_engine(self.engine)
  File "/Users/shimingr/mlops/airflow/venv2/lib/python3.9/site-packages/pandas/io/parsers/readers.py", line 1040, in _make_engine
    return mapping[engine](self.f, **self.options)  # type: ignore[call-arg]
  File "/Users/shimingr/mlops/airflow/venv2/lib/python3.9/site-packages/pandas/io/parsers/c_parser_wrapper.py", line 51, in __init__
    self._open_handles(src, kwds)
  File "/Users/shimingr/mlops/airflow/venv2/lib/python3.9/site-packages/pandas/io/parsers/base_parser.py", line 222, in _open_handles
    self.handles = get_handle(
  File "/Users/shimingr/mlops/airflow/venv2/lib/python3.9/site-packages/pandas/io/common.py", line 609, in get_handle
    ioargs = _get_filepath_or_buffer(
  File "/Users/shimingr/mlops/airflow/venv2/lib/python3.9/site-packages/pandas/io/common.py", line 358, in _get_filepath_or_buffer
    file_obj = fsspec.open(
  File "/Users/shimingr/mlops/airflow/venv2/lib/python3.9/site-packages/fsspec/core.py", line 452, in open
    return open_files(
  File "/Users/shimingr/mlops/airflow/venv2/lib/python3.9/site-packages/fsspec/core.py", line 286, in open_files
    fs, fs_token, paths = get_fs_token_paths(
  File "/Users/shimingr/mlops/airflow/venv2/lib/python3.9/site-packages/fsspec/core.py", line 622, in get_fs_token_paths
    cls = get_filesystem_class(protocol)
  File "/Users/shimingr/mlops/airflow/venv2/lib/python3.9/site-packages/fsspec/registry.py", line 221, in get_filesystem_class
    raise ImportError(bit["err"]) from e
ImportError: Install s3fs to access S3
[2021-11-18 00:31:16,810] {local_task_job.py:154} INFO - Task exited with return code 1
[2021-11-18 00:31:16,844] {local_task_job.py:264} INFO - 0 downstream tasks scheduled from follow-on schedule check
