[2021-11-17 22:34:46,041] {taskinstance.py:1035} INFO - Dependencies all met for <TaskInstance: mwaa-sm-customer-churn-dag.train manual__2021-11-18T06:34:33.593117+00:00 [queued]>
[2021-11-17 22:34:46,049] {taskinstance.py:1035} INFO - Dependencies all met for <TaskInstance: mwaa-sm-customer-churn-dag.train manual__2021-11-18T06:34:33.593117+00:00 [queued]>
[2021-11-17 22:34:46,049] {taskinstance.py:1241} INFO - 
--------------------------------------------------------------------------------
[2021-11-17 22:34:46,049] {taskinstance.py:1242} INFO - Starting attempt 1 of 1
[2021-11-17 22:34:46,049] {taskinstance.py:1243} INFO - 
--------------------------------------------------------------------------------
[2021-11-17 22:34:46,060] {taskinstance.py:1262} INFO - Executing <Task(SageMakerTrainingOperator): train> on 2021-11-18 06:34:33.593117+00:00
[2021-11-17 22:34:46,065] {standard_task_runner.py:52} INFO - Started process 15053 to run task
[2021-11-17 22:34:46,072] {standard_task_runner.py:76} INFO - Running: ['airflow', 'tasks', 'run', 'mwaa-sm-customer-churn-dag', 'train', 'manual__2021-11-18T06:34:33.593117+00:00', '--job-id', '13', '--raw', '--subdir', 'DAGS_FOLDER/mwaa-customer-churn-dag.py', '--cfg-path', '/var/folders/m8/kcmtvg3x5639v8tv9jcxd6700000gn/T/tmp_ru9p0z0', '--error-file', '/var/folders/m8/kcmtvg3x5639v8tv9jcxd6700000gn/T/tmpqeh9ydjq']
[2021-11-17 22:34:46,074] {standard_task_runner.py:77} INFO - Job 13: Subtask train
[2021-11-17 22:34:46,121] {logging_mixin.py:109} INFO - Running <TaskInstance: mwaa-sm-customer-churn-dag.train manual__2021-11-18T06:34:33.593117+00:00 [running]> on host 1.0.0.127.in-addr.arpa
[2021-11-17 22:34:46,181] {taskinstance.py:1427} INFO - Exporting the following env vars:
AIRFLOW_CTX_DAG_OWNER=airflow
AIRFLOW_CTX_DAG_ID=mwaa-sm-customer-churn-dag
AIRFLOW_CTX_TASK_ID=train
AIRFLOW_CTX_EXECUTION_DATE=2021-11-18T06:34:33.593117+00:00
AIRFLOW_CTX_DAG_RUN_ID=manual__2021-11-18T06:34:33.593117+00:00
[2021-11-17 22:34:46,181] {sagemaker_base.py:89} INFO - Preprocessing the config and doing required s3_operations
[2021-11-17 22:34:46,182] {sagemaker_base.py:95} INFO - After preprocessing the config is:
 {
    "AlgorithmSpecification": {
        "TrainingImage": "433757028032.dkr.ecr.us-west-2.amazonaws.com/xgboost:1",
        "TrainingInputMode": "File"
    },
    "HyperParameters": {
        "eta": "0.2",
        "gamma": "4",
        "max_depth": "5",
        "min_child_weight": "6",
        "num_round": "100",
        "objective": "binary:logistic",
        "subsample": "0.8"
    },
    "InputDataConfig": [
        {
            "ChannelName": "train",
            "ContentType": "text/csv",
            "DataSource": {
                "S3DataSource": {
                    "S3DataDistributionType": "FullyReplicated",
                    "S3DataType": "S3Prefix",
                    "S3Uri": "s3://shimingr-data/processed/train/"
                }
            }
        },
        {
            "ChannelName": "validation",
            "ContentType": "text/csv",
            "DataSource": {
                "S3DataSource": {
                    "S3DataDistributionType": "FullyReplicated",
                    "S3DataType": "S3Prefix",
                    "S3Uri": "s3://shimingr-data/processed/validation/"
                }
            }
        }
    ],
    "OutputDataConfig": {
        "S3OutputPath": "s3://shimingr-data/model/"
    },
    "ResourceConfig": {
        "InstanceCount": 1,
        "InstanceType": "ml.m5.4xlarge",
        "VolumeSizeInGB": 5
    },
    "RoleArn": "arn:aws:iam::846634201516:role/AmazonMWAA-SageMaker-Role",
    "StoppingCondition": {
        "MaxRuntimeInSeconds": 86400
    },
    "TrainingJobName": "mwaa-sm-training-job-5d42ae5e26ce476ea3927ed47a19b245"
}
[2021-11-17 22:34:46,183] {base_aws.py:401} INFO - Airflow Connection: aws_conn_id=airflow-sagemaker
[2021-11-17 22:34:46,188] {base_aws.py:424} WARNING - Unable to use Airflow Connection for credentials.
[2021-11-17 22:34:46,188] {base_aws.py:425} INFO - Fallback on boto3 credential strategy
[2021-11-17 22:34:46,189] {base_aws.py:428} INFO - Creating session using boto3 credential strategy region_name=None
[2021-11-17 22:34:46,213] {logging_mixin.py:109} WARNING - /Users/shimingr/mlops/airflow/venv2/lib/python3.9/site-packages/airflow/providers/amazon/aws/hooks/base_aws.py:494 DeprecationWarning: client_type is deprecated. Set client_type from class attribute.
[2021-11-17 22:34:46,218] {credentials.py:1222} INFO - Found credentials in shared credentials file: ~/.aws/credentials
[2021-11-17 22:34:46,490] {sagemaker_training.py:101} INFO - Creating SageMaker training job mwaa-sm-training-job-5d42ae5e26ce476ea3927ed47a19b245.
[2021-11-17 22:34:46,491] {base_aws.py:401} INFO - Airflow Connection: aws_conn_id=airflow-sagemaker
[2021-11-17 22:34:46,496] {base_aws.py:424} WARNING - Unable to use Airflow Connection for credentials.
[2021-11-17 22:34:46,497] {base_aws.py:425} INFO - Fallback on boto3 credential strategy
[2021-11-17 22:34:46,497] {base_aws.py:428} INFO - Creating session using boto3 credential strategy region_name=None
[2021-11-17 22:34:46,513] {credentials.py:1222} INFO - Found credentials in shared credentials file: ~/.aws/credentials
[2021-11-17 22:34:47,163] {sagemaker.py:790} INFO - 2021-11-18 06:34:47 Starting - Starting the training job
[2021-11-17 22:35:47,166] {base_aws.py:401} INFO - Airflow Connection: aws_conn_id=airflow-sagemaker
[2021-11-17 22:35:47,177] {base_aws.py:424} WARNING - Unable to use Airflow Connection for credentials.
[2021-11-17 22:35:47,178] {base_aws.py:425} INFO - Fallback on boto3 credential strategy
[2021-11-17 22:35:47,178] {base_aws.py:428} INFO - Creating session using boto3 credential strategy region_name=None
[2021-11-17 22:35:47,196] {credentials.py:1222} INFO - Found credentials in shared credentials file: ~/.aws/credentials
[2021-11-17 22:35:47,717] {sagemaker.py:626} INFO - 2021-11-18 06:34:48 Starting - Launching requested ML instances
[2021-11-17 22:36:48,210] {sagemaker.py:626} INFO - 2021-11-18 06:35:55 Starting - Preparing the instances for training
[2021-11-17 22:37:48,696] {sagemaker.py:626} INFO - 2021-11-18 06:37:19 Downloading - Downloading input data
2021-11-18 06:37:19 Failed - Training job failed
[2021-11-17 22:38:38,118] {local_task_job.py:191} WARNING - The recorded hostname 1.0.0.127.in-addr.arpa does not match this instance's hostname Shimings-MacBook-Air.local
[2021-11-17 22:38:38,147] {process_utils.py:100} INFO - Sending Signals.SIGTERM to GPID 15053
[2021-11-17 22:38:38,154] {taskinstance.py:1411} ERROR - Received SIGTERM. Terminating subprocesses.
[2021-11-17 22:38:38,199] {taskinstance.py:1703} ERROR - Task failed with exception
Traceback (most recent call last):
  File "/Users/shimingr/mlops/airflow/venv2/lib/python3.9/site-packages/airflow/models/taskinstance.py", line 1332, in _run_raw_task
    self._execute_task_with_callbacks(context)
  File "/Users/shimingr/mlops/airflow/venv2/lib/python3.9/site-packages/airflow/models/taskinstance.py", line 1458, in _execute_task_with_callbacks
    result = self._execute_task(context, self.task)
  File "/Users/shimingr/mlops/airflow/venv2/lib/python3.9/site-packages/airflow/models/taskinstance.py", line 1514, in _execute_task
    result = execute_callable(context=context)
  File "/Users/shimingr/mlops/airflow/venv2/lib/python3.9/site-packages/airflow/providers/amazon/aws/operators/sagemaker_training.py", line 102, in execute
    response = self.hook.create_training_job(
  File "/Users/shimingr/mlops/airflow/venv2/lib/python3.9/site-packages/airflow/providers/amazon/aws/hooks/sagemaker.py", line 343, in create_training_job
    self.check_training_status_with_log(
  File "/Users/shimingr/mlops/airflow/venv2/lib/python3.9/site-packages/airflow/providers/amazon/aws/hooks/sagemaker.py", line 825, in check_training_status_with_log
    time.sleep(check_interval)
  File "/Users/shimingr/mlops/airflow/venv2/lib/python3.9/site-packages/airflow/models/taskinstance.py", line 1413, in signal_handler
    raise AirflowException("Task received SIGTERM signal")
airflow.exceptions.AirflowException: Task received SIGTERM signal
[2021-11-17 22:38:38,231] {taskinstance.py:1270} INFO - Marking task as FAILED. dag_id=mwaa-sm-customer-churn-dag, task_id=train, execution_date=20211118T063433, start_date=20211118T063446, end_date=20211118T063838
[2021-11-17 22:38:38,267] {standard_task_runner.py:88} ERROR - Failed to execute job 13 for task train
Traceback (most recent call last):
  File "/Users/shimingr/mlops/airflow/venv2/lib/python3.9/site-packages/airflow/task/task_runner/standard_task_runner.py", line 85, in _start_by_fork
    args.func(args, dag=self.dag)
  File "/Users/shimingr/mlops/airflow/venv2/lib/python3.9/site-packages/airflow/cli/cli_parser.py", line 48, in command
    return func(*args, **kwargs)
  File "/Users/shimingr/mlops/airflow/venv2/lib/python3.9/site-packages/airflow/utils/cli.py", line 92, in wrapper
    return f(*args, **kwargs)
  File "/Users/shimingr/mlops/airflow/venv2/lib/python3.9/site-packages/airflow/cli/commands/task_command.py", line 292, in task_run
    _run_task_by_selected_method(args, dag, ti)
  File "/Users/shimingr/mlops/airflow/venv2/lib/python3.9/site-packages/airflow/cli/commands/task_command.py", line 107, in _run_task_by_selected_method
    _run_raw_task(args, ti)
  File "/Users/shimingr/mlops/airflow/venv2/lib/python3.9/site-packages/airflow/cli/commands/task_command.py", line 180, in _run_raw_task
    ti._run_raw_task(
  File "/Users/shimingr/mlops/airflow/venv2/lib/python3.9/site-packages/airflow/utils/session.py", line 70, in wrapper
    return func(*args, session=session, **kwargs)
  File "/Users/shimingr/mlops/airflow/venv2/lib/python3.9/site-packages/airflow/models/taskinstance.py", line 1332, in _run_raw_task
    self._execute_task_with_callbacks(context)
  File "/Users/shimingr/mlops/airflow/venv2/lib/python3.9/site-packages/airflow/models/taskinstance.py", line 1458, in _execute_task_with_callbacks
    result = self._execute_task(context, self.task)
  File "/Users/shimingr/mlops/airflow/venv2/lib/python3.9/site-packages/airflow/models/taskinstance.py", line 1514, in _execute_task
    result = execute_callable(context=context)
  File "/Users/shimingr/mlops/airflow/venv2/lib/python3.9/site-packages/airflow/providers/amazon/aws/operators/sagemaker_training.py", line 102, in execute
    response = self.hook.create_training_job(
  File "/Users/shimingr/mlops/airflow/venv2/lib/python3.9/site-packages/airflow/providers/amazon/aws/hooks/sagemaker.py", line 343, in create_training_job
    self.check_training_status_with_log(
  File "/Users/shimingr/mlops/airflow/venv2/lib/python3.9/site-packages/airflow/providers/amazon/aws/hooks/sagemaker.py", line 825, in check_training_status_with_log
    time.sleep(check_interval)
  File "/Users/shimingr/mlops/airflow/venv2/lib/python3.9/site-packages/airflow/models/taskinstance.py", line 1413, in signal_handler
    raise AirflowException("Task received SIGTERM signal")
airflow.exceptions.AirflowException: Task received SIGTERM signal
[2021-11-17 22:38:38,339] {process_utils.py:66} INFO - Process psutil.Process(pid=15053, status='terminated', exitcode=1, started='22:34:46') (15053) terminated with exit code 1
